Workbook

Sheet Start Here
B1: Cummins 2026 Forecast: Start Here
B2: A plain-English guide to this workbook. No finance background needed.
B4: What this workbook does
B5: Cummins is an Indiana-based company that makes engines, parts and power generators. This workbook predicts its sales and profit
B6: for the rest of 2026, business by business. The Q3 2026 prediction (v1.1) was frozen on October 8, 2026, before Cummins reports.
B7: When the real results come out (early November 2026), the Variance tab shows how close the prediction was, and why.
B9: How to use it in 3 steps
B10: 1. Look | C10: Open the Dashboard for the headline numbers and charts. | D10: =HYPERLINK("#'Dashboard'!A1","Go to Dashboard →") -> Go to Dashboard →
B11: 2. Play | C11: On the Dashboard, pick Bear, Base, Bull or Custom in the scenario box to see what happens if demand surprises. | D11: =HYPERLINK("#'Dashboard'!A1","Go to Dashboard →") -> Go to Dashboard →
B12: 3. Score | C12: After Cummins reports Q3, type its numbers into the yellow cells on the Variance tab. | D12: =HYPERLINK("#'Variance'!A1","Go to Variance →") -> Go to Variance →
B14: Tab guide
B15: Tab | C15: What it shows | D15: Can I change it?
B16: =HYPERLINK("#'Dashboard'!A1","Dashboard") -> Dashboard | C16: Headline numbers, scenario explorer and charts | D16: Yes: the scenario box and yellow Custom cells
B17: =HYPERLINK("#'Inputs'!A1","Inputs") -> Inputs | C17: The assumptions behind the forecast, each with a reason | D17: Yes, but this changes the locked budget
B18: =HYPERLINK("#'Forecast'!A1","Forecast") -> Forecast | C18: Q3 and Q4 2026 predictions for each business | D18: No: all calculated
B19: =HYPERLINK("#'Variance'!A1","Variance") -> Variance | C19: Prediction vs real results, once they are out | D19: Yes: the yellow cells, after results
B20: =HYPERLINK("#'Historicals'!A1","Historicals") -> Historicals | C20: What Cummins actually reported, Q1 2025 to Q2 2026 | D20: No: copied from official filings
B21: =HYPERLINK("#'Backtest'!A1","Backtest") -> Backtest | C21: How accurate this method was on past quarters | D21: No: all calculated
B22: =HYPERLINK("#'Change Log'!A1","Change Log") -> Change Log | C22: What changed after the review, and why | D22: No: a record
B23: =HYPERLINK("#'Scenario Calc'!A1","Scenario Calc") -> Scenario Calc | C23: The maths behind the scenario explorer | D23: No: all calculated
B24: =HYPERLINK("#'Chart Data'!A1","Chart Data") -> Chart Data | C24: Numbers that feed the dashboard charts | D24: No: all calculated
B26: Colour guide
B27: 1,234 | C27: Blue number: typed in from an official source or an assumption
B28: 1,234 | C28: Black number: calculated by a formula
B29: 1,234 | C29: Green number: pulled from another tab
B30: type here | C30: Yellow cell: you can type here
B31: Beat | C31: Green box: better than budget, or inside the company's targets
B32: Missed | C32: Red box: worse than budget, or outside the company's targets
B33: Engine | C33: Each business keeps the same colour on every tab and chart
B34: Components | C34: Each business keeps the same colour on every tab and chart
B35: Distribution | C35: Each business keeps the same colour on every tab and chart
B36: Power Systems | C36: Each business keeps the same colour on every tab and chart
B37: Accelera | C37: Each business keeps the same colour on every tab and chart
B39: Words used in this workbook
B40: Net sales | C40: Money received from customers, after removing sales between Cummins' own divisions.
B41: EBITDA | C41: Profit before interest, taxes and depreciation (wear and tear on equipment). A common measure of operating profit.
B42: Adjusted EBITDA | C42: EBITDA without one-off charges, such as the cost of closing or selling a business.
B43: Margin | C43: Profit as a share of sales. An 18% margin means 18 cents of profit for every $1 of sales.
B44: YoY | C44: Year over year: a quarter compared with the same quarter a year earlier.
B45: Segment | C45: One of Cummins' five business divisions (Engine, Components, Distribution, Power Systems, Accelera).
...

Sheet Dashboard
B1: Cummins 2026 Forecast Dashboard
B2: Will Cummins hit its 2026 targets? Budget v1.1 locked October 8, 2026, before Q3 results (see Change Log). $B = billions of US dollars.
B3: Jump to: | C3: =HYPERLINK("#'Start Here'!A1","Start Here") -> Start Here | D3: =HYPERLINK("#'Inputs'!A1","Inputs") -> Inputs | E3: =HYPERLINK("#'Forecast'!A1","Forecast") -> Forecast | F3: =HYPERLINK("#'Variance'!A1","Variance") -> Variance | G3: =HYPERLINK("#'Backtest'!A1","Backtest") -> Backtest | H3: =HYPERLINK("#'Change Log'!A1","Change Log") -> Change Log | I3: =HYPERLINK("#'Historicals'!A1","Historicals") -> Historicals | J3: =HYPERLINK("#'Scenario Calc'!A1","Scenario Calc") -> Scenario Calc
B5: 2026 SALES (FORECAST) | E5: 2026 PROFIT (ADJUSTED EBITDA) | H5: PROFIT MARGIN | K5: ON TRACK WITH COMPANY TARGETS?
B6: =Forecast!I17 -> 37313.453 | E6: =Forecast!I29 -> 6785.4066 | H6: =Forecast!I30 -> 0.1818488 | K6: =IF(AND(Forecast!B35="Yes",Forecast!B38="Yes"),"Yes","Not quite") -> Yes
B8: ="Up "&TEXT(Forecast!K17,"0.0%")&" on 2025's "&TEXT(Forecast!J17/1000,"$0.0")&"B" -> Up 10.8% on 2025's $33.7B | E8: ="Up "&TEXT(Forecast!I29/Forecast!J29-1,"0%")&" on 2025's "&TEXT(Forecast!J29/1000,"$0.0")&"B" -> Up 16% on 2025's $5.8B | H8: ="About "&TEXT(Forecast!I30*100,"0")&" cents of profit per $1 of sales" -> About 18 cents of profit per $1 of sales | K8: ="Targets: sales +"&TEXT(Inputs!$B$31,"0%")&" to +"&TEXT(Inputs!$B$32,"0%")&", margin "&TEXT(Inputs!$B$33,"0.0%")&" to "&TEXT(Inputs!$B$34,"0.0%") -> Targets: sales +10% to +13%, margin 18.0% to 18.5%
B10: Q3 2026 check-in: the numbers to beat
B11: Q3 sales budget | E11: Q3 profit margin budget | H11: Wall Street expects (Q3 sales) | K11: =IF(Variance!C11="","Waiting for results (early Nov 2026)",IF(Variance!D11>=0,"Sales BEAT budget by "&TEXT(Variance!D11,"$#,##0")&"M","Sales MISSED budget by "&TEXT(-Variance!D11,"$#,##0")&"M")) -> Waiting for results (early Nov 2026)
B12: =Forecast!C17 -> 9481.9344 | E12: =Forecast!C30 -> 0.18565201 | H12: =Inputs!$B$53 -> 9840
B14: Scenario explorer: what if demand turns out better or worse?
B15: Pick a scenario → | D15: Base | F15: =IF(D15="Bear","Bear: truck builds and data center orders both disappoint by about as much as this method has missed before (Backtest tab), and margins slip half a point.",IF(D15="Bull","Bull: the same-sized surprise in the good direction: truck-linked growth 8 points higher, data center 7 points higher, margins half a point higher.",IF(D15="Custom","Custom: type your own changes in the yellow Custom column below.","Base: the locked budget, unchanged."))) -> Base: the locked budget, unchanged.
B17: Change vs budget, H2 2026 | E17: Bear | F17: Base | G17: Bull | H17: Custom | I17: Your pick
B18: Truck demand: Engine and Components growth | E18: -0.08 | F18: 0 | G18: 0.08 | H18: -0.05 | I18: =INDEX(E18:H18,MATCH($D$15,$E$17:$H$17,0)) -> 0
B19: Data center demand: Power Systems and Distribution growth | E19: -0.07 | F19: 0 | G19: 0.07 | H19: 0 | I19: =INDEX(E19:H19,MATCH($D$15,$E$17:$H$17,0)) -> 0
B20: Profit margin on the four main businesses | E20: -0.005 | F20: 0 | G20: 0.005 | H20: 0 | I20: =INDEX(E20:H20,MATCH($D$15,$E$17:$H$17,0)) -> 0
B22: Full-year 2026 result | E22: Bear | F22: Base | G22: Bull | H22: Custom | I22: Your pick | J22: Target low | K22: Target high
B23: Sales | E23: ='Scenario Calc'!C29 -> 36073.579 | F23: ='Scenario Calc'!D29 -> 37313.453 | G23: ='Scenario Calc'!E29 -> 38553.326 | H23: ='Scenario Calc'!F29 -> 36907.806 | I23: ='Scenario Calc'!G29 -> 37313.453
B24: Sales growth vs 2025 | E24: ='Scenario Calc'!C30 -> 0.071386361 | F24: ='Scenario Calc'!D30 -> 0.10821065 | G24: ='Scenario Calc'!E30 -> 0.14503494 | H24: ='Scenario Calc'!F30 -> 0.096162941 | I24: ='Scenario Calc'!G30 -> 0.10821065 | J24: =Inputs!$B$31 -> 0.1 | K24: =Inputs!$B$32 -> 0.13
B25: Adjusted EBITDA (profit) | E25: ='Scenario Calc'!C37 -> 6430.7792 | F25: ='Scenario Calc'!D37 -> 6785.4066 | G25: ='Scenario Calc'!E37 -> 7155.2845 | H25: ='Scenario Calc'!F37 -> 6714.0297 | I25: ='Scenario Calc'!G37 -> 6785.4066
B26: Profit margin | E26: ='Scenario Calc'!C38 -> 0.1782684 | F26: ='Scenario Calc'!D38 -> 0.1818488 | G26: ='Scenario Calc'!E38 -> 0.18559448 | H26: ='Scenario Calc'!F38 -> 0.18191354 | I26: ='Scenario Calc'!G38 -> 0.1818488 | J26: =Inputs!$B$33 -> 0.18 | K26: =Inputs!$B$34 -> 0.185
B27: Hits both company targets? | E27: =IF(AND(E24>=$J$24,E26>=$J$26),"Yes","No") -> No | F27: =IF(AND(F24>=$J$24,F26>=$J$26),"Yes","No") -> Yes | G27: =IF(AND(G24>=$J$24,G26>=$J$26),"Yes","No") -> Yes | H27: =IF(AND(H24>=$J$24,H26>=$J$26),"Yes","No") -> No | I27: =IF(AND(I24>=$J$24,I26>=$J$26),"Yes","No") -> Yes
B28: Scenarios are what-ifs only: they never change the locked budget that is scored on the Variance tab.
B30: The five businesses: where sales and profit come from
B31: Business | D31: What it sells | H31: 2025 sales | I31: 2026 forecast | J31: Growth | K31: Profit margin | L31: Share of profit
B32: Engine | D32: Diesel and natural gas engines for trucks, buses and machinery | H32: =Forecast!J10 -> 10875 | I32: =Forecast!I10 -> 11978.006 | J32: =Forecast!K10 -> 0.10142584 | K32: =Forecast!I20/Forecast!I10 -> 0.12883745 | L32: =Forecast!I20/SUM(Forecast!$I$20:$I$23) -> 0.21343415
B33: Components | D33: Axles, brakes, turbochargers and exhaust-cleaning systems | H33: =Forecast!J11 -> 10149 | I33: =Forecast!I11 -> 11129.99 | J33: =Forecast!K11 -> 0.096658784 | K33: =Forecast!I21/Forecast!I11 -> 0.13895501 | L33: =Forecast!I21/SUM(Forecast!$I$20:$I$23) -> 0.21389777
B34: Distribution | D34: Dealers that sell and service Cummins products, incl. generators | H34: =Forecast!J12 -> 12405 | I34: =Forecast!I12 -> 13740.67 | J34: =Forecast!K12 -> 0.10767191 | K34: =Forecast!I22/Forecast!I12 -> 0.13896812 | L34: =Forecast!I22/SUM(Forecast!$I$20:$I$23) -> 0.26409513
B35: Power Systems | D35: Large generators, including backup power for data centers | H35: =Forecast!J13 -> 7463 | I35: =Forecast!I13 -> 8784.63 | J35: =Forecast!K13 -> 0.17709098 | K35: =Forecast!I23/Forecast!I13 -> 0.25397859 | L35: =Forecast!I23/SUM(Forecast!$I$20:$I$23) -> 0.30857295
B36: Accelera | D36: Batteries and electric drive systems (zero emissions) | H36: =Forecast!J14 -> 460 | I36: =Forecast!I14 -> 376.84 | J36: =Forecast!K14 -> -0.18078261 | K36: Loss-making | L36: ="Adj. loss "&TEXT(-(Forecast!I24+Forecast!I28),"$#,##0")&"M" -> Adj. loss $277M
B37: Share of profit = each business's 2026 EBITDA as a share of the four profitable businesses combined.
B39: Charts

Sheet Inputs
A1: Forecast drivers (edit blue cells only)
A2: The assumptions behind the budget. Changing a yellow cell changes the locked budget; to explore what-ifs, use the Dashboard's scenario explorer instead.
A3: =HYPERLINK("#'Dashboard'!A1","← Back to Dashboard") -> ← Back to Dashboard
A4: Driver | B4: Q3 2026 | C4: Q4 2026 | D4: Rationale
A5: Engine
A6: Engine unit growth (YoY) | B6: 0.12 | C6: 0.19 | D6: v1.1: with +3.5% price gives segment sales +16% / +23%. Sized so H2 lands inside Cummins' FY Engine guide of +9% to +14% (Aug 4, 2026 call). Q3 kept ~2% below Q2 (seasonal dip; 2024-25 dips of 8-10% were downturn years). NA heavy-duty build 240-250k, 'largely set' for H2.
A7: Engine price/mix per unit (YoY) | B7: 0.035 | C7: 0.035 | D7: Sales per unit rose about 3% YoY in Q2'26 (pricing plus China off-highway mix).
A8: Engine EBITDA margin | B8: 0.136 | C8: 0.146 | D8: v1.1: FY Engine guide 12.5%-13.25% (Aug 4, 2026); its midpoint needs ~14.1% in H2 because H1 was 11.6%. H2 incentive comp ~$25M/qtr lower than Q2 (CFO).
A9: Components
A10: Components sales growth (YoY) | B10: 0.16 | C10: 0.23 | D10: v1.1: FY Components guide +8% to +13% (Aug 4, 2026). Truck-linked like Engine; Q3 about 6.5% below Q2 (seasonal), recovery weighted to Q4.
A11: Components EBITDA margin | B11: 0.1425 | C11: 0.1475 | D11: v1.1: FY guide 13.5%-14.25%; its midpoint needs ~14.5% in H2 (H1 was 13.2%).
A12: Distribution
A13: Distribution sales growth (YoY) | B13: 0.11 | C13: 0.15 | D13: v1.1: FY guide +9% to +14% (Aug 4, 2026); H1 was +8.3%. Data center generator demand; Q4 2025 base weakest in H2.
A14: Distribution EBITDA margin | B14: 0.139 | C14: 0.139 | D14: v1.1: current FY guide 13.5%-14.25% (lowered on Aug 4 from 13.7%-14.7%, which v1.0 wrongly cited). H1 was 13.9%.
A15: Power Systems
A16: Power Systems sales growth (YoY) | B16: 0.18 | C16: 0.15 | D16: v1.1: FY guide +14% to +19% (Aug 4, 2026); H1 already +19%. Q4 2025 base is tougher (+11% YoY then). FY lands ~+17.7%.
A17: Power Systems EBITDA margin | B17: 0.24 | C17: 0.242 | D17: v1.1: FY guide 25.0%-25.75%. H1 ran 26.8%, so the midpoint implies ~24.1% in H2. v1.0's 25.5% put FY at 26.1%, above the range.
A18: Accelera and corporate
A19: Accelera sales growth (YoY) | B19: -0.46 | C19: -0.5 | D19: v1.1: FY Accelera revenue guide $350M-$400M (Aug 4, 2026); H1 was $246M, so H2 is ~$130M (~$65M/qtr) after the electrolyzer exit and fuel cell sale.
A20: Accelera EBITDA ($mm) | B20: -65 | C20: -65 | D20: v1.1: FY loss guide $260M-$290M excluding the fuel cell charge; H1 underlying loss $147M, so H2 ~$130M.
A21: Eliminations (% of total segment sales) | B21: 0.187 | C21: 0.187 | D21: v1.1: Q3'25 18.6%, Q4'25 17.8%, Q1'26 19.1%, Q2'26 19.2%; average of the last four quarters.
A22: Eliminations and corporate EBITDA ($mm) | B22: -25 | C22: -25 | D22: v1.1: Q2'26 was -$48M including an incentive-comp top-up; CFO said H2 incentive comp ~$25M/qtr lower. 2025 H2 ran +$21M/+$22M.
A23: Below EBITDA (for EPS)
A24: Depreciation and amortization ($mm) | B24: 285 | C24: 290 | D24: Q1'26 $280M, Q2'26 $280M; rising with capacity investment.
A25: Interest expense ($mm) | B25: 80 | C25: 80 | D25: Q1'26 $76M, Q2'26 $80M.
A26: Tax rate | B26: 0.23 | C26: 0.23 | D26: Cummins' 2026 effective tax rate guidance of about 23.0% excluding discrete items (Q2 2026 release).
A27: Noncontrolling interests ($mm) | B27: 32 | C27: 32 | D27: Q1'26 $26M, Q2'26 $36M.
A28: Diluted shares (millions) | B28: 138.5 | C28: 138.5 | D28: Q2'26 diluted share count 138.5M.
A30: Management guidance (for the FY2026 check)
A31: FY2026 revenue growth - low | B31: 0.1 | D31: Raised Aug 4, 2026 from +8% to +11%.
A32: FY2026 revenue growth - high | B32: 0.13
A33: FY2026 EBITDA margin - low | B33: 0.18 | D33: Excludes the Q1'26 fuel cell sale charges.
A34: FY2026 EBITDA margin - high | B34: 0.185
A35: Source: Cummins Q2 2026 earnings release (8-K Ex.99, Aug 4 2026), segment tables: https://www.sec.gov/Archives/edgar/data/0000026172/000002617226000026/cmi2026q28-kex99.htm
A37: Segment guidance for FY2026 (Cummins Q2 2026 earnings call, Aug 4, 2026)
A38: Segment | B38: Low | C38: High | D38: Measure
A39: Engine revenue growth | B39: 0.09 | C39: 0.14 | D39: FY2026 vs FY2025
A40: Engine EBITDA margin | B40: 0.125 | C40: 0.1325 | D40: FY2026, % of segment sales
A41: Components revenue growth | B41: 0.08 | C41: 0.13 | D41: FY2026 vs FY2025
A42: Components EBITDA margin | B42: 0.135 | C42: 0.1425 | D42: FY2026, % of segment sales
...

Sheet Forecast
A1: Q3 and Q4 2026 budget by segment ($ millions)
A2: What Cummins is forecast to sell and earn in Q3 and Q4 2026, by business. Orange columns are the forecast; B = budget, A = actual.
A3: =HYPERLINK("#'Dashboard'!A1","← Back to Dashboard") -> ← Back to Dashboard
B4: Q3 2025A | C4: Q3 2026B | D4: YoY | E4: Q4 2025A | F4: Q4 2026B | G4: YoY | H4: H1 2026A | I4: FY2026B | J4: FY2025A | K4: YoY
A5: Engine drivers
A6: Engine units | B6: =Historicals!D40 -> 135100 | C6: =B6*(1+Inputs!$B$6) -> 151312 | D6: =IF(B6=0,0,C6/B6-1) -> 0.12 | E6: =Historicals!E40 -> 131100 | F6: =E6*(1+Inputs!$C$6) -> 156009 | G6: =IF(E6=0,0,F6/E6-1) -> 0.19 | H6: =Historicals!G40+Historicals!H40 -> 305500 | I6: =H6+C6+F6 -> 612821 | J6: =Historicals!F40 -> 554200 | K6: =IF(J6=0,0,I6/J6-1) -> 0.10577589
A7: Engine sales per unit ($000) | B7: =Historicals!D41 -> 19.282013 | C7: =B7*(1+Inputs!$B$7) -> 19.956884 | E7: =Historicals!E41 -> 19.832189 | F7: =E7*(1+Inputs!$C$7) -> 20.526316
A9: Segment sales
A10: Engine | B10: =Historicals!D6 -> 2605 | C10: =C6*C7/1000 -> 3019.716 | D10: =IF(B10=0,0,C10/B10-1) -> 0.1592 | E10: =Historicals!E6 -> 2600 | F10: =F6*F7/1000 -> 3202.29 | G10: =IF(E10=0,0,F10/E10-1) -> 0.23165 | H10: =Historicals!G6+Historicals!H6 -> 5756 | I10: =H10+C10+F10 -> 11978.006 | J10: =Historicals!F6 -> 10875 | K10: =IF(J10=0,0,I10/J10-1) -> 0.10142584
A11: Components | B11: =Historicals!D7 -> 2329 | C11: =B11*(1+Inputs!$B$10) -> 2701.64 | D11: =IF(B11=0,0,C11/B11-1) -> 0.16 | E11: =Historicals!E7 -> 2445 | F11: =E11*(1+Inputs!$C$10) -> 3007.35 | G11: =IF(E11=0,0,F11/E11-1) -> 0.23 | H11: =Historicals!G7+Historicals!H7 -> 5421 | I11: =H11+C11+F11 -> 11129.99 | J11: =Historicals!F7 -> 10149 | K11: =IF(J11=0,0,I11/J11-1) -> 0.096658784
A12: Distribution | B12: =Historicals!D8 -> 3172 | C12: =B12*(1+Inputs!$B$13) -> 3520.92 | D12: =IF(B12=0,0,C12/B12-1) -> 0.11 | E12: =Historicals!E8 -> 3285 | F12: =E12*(1+Inputs!$C$13) -> 3777.75 | G12: =IF(E12=0,0,F12/E12-1) -> 0.15 | H12: =Historicals!G8+Historicals!H8 -> 6442 | I12: =H12+C12+F12 -> 13740.67 | J12: =Historicals!F8 -> 12405 | K12: =IF(J12=0,0,I12/J12-1) -> 0.10767191
A13: Power Systems | B13: =Historicals!D9 -> 1996 | C13: =B13*(1+Inputs!$B$16) -> 2355.28 | D13: =IF(B13=0,0,C13/B13-1) -> 0.18 | E13: =Historicals!E9 -> 1929 | F13: =E13*(1+Inputs!$C$16) -> 2218.35 | G13: =IF(E13=0,0,F13/E13-1) -> 0.15 | H13: =Historicals!G9+Historicals!H9 -> 4211 | I13: =H13+C13+F13 -> 8784.63 | J13: =Historicals!F9 -> 7463 | K13: =IF(J13=0,0,I13/J13-1) -> 0.17709098
A14: Accelera | B14: =Historicals!D10 -> 121 | C14: =B14*(1+Inputs!$B$19) -> 65.34 | D14: =IF(B14=0,0,C14/B14-1) -> -0.46 | E14: =Historicals!E10 -> 131 | F14: =E14*(1+Inputs!$C$19) -> 65.5 | G14: =IF(E14=0,0,F14/E14-1) -> -0.5 | H14: =Historicals!G10+Historicals!H10 -> 246 | I14: =H14+C14+F14 -> 376.84 | J14: =Historicals!F10 -> 460 | K14: =IF(J14=0,0,I14/J14-1) -> -0.18078261
A15: Total segment sales | B15: =SUM(B10:B14) -> 10223 | C15: =SUM(C10:C14) -> 11662.896 | D15: =IF(B15=0,0,C15/B15-1) -> 0.14084867 | E15: =SUM(E10:E14) -> 10390 | F15: =SUM(F10:F14) -> 12271.24 | G15: =IF(E15=0,0,F15/E15-1) -> 0.18106256 | H15: =SUM(H10:H14) -> 22076 | I15: =SUM(I10:I14) -> 46010.136 | J15: =SUM(J10:J14) -> 41352 | K15: =IF(J15=0,0,I15/J15-1) -> 0.11264597
A16: Intersegment eliminations | B16: =Historicals!D12 -> -1906 | C16: =-C15*Inputs!$B$21 -> -2180.9616 | E16: =Historicals!E12 -> -1854 | F16: =-F15*Inputs!$C$21 -> -2294.7219 | H16: =Historicals!G12+Historicals!H12 -> -4221 | I16: =H16+C16+F16 -> -8696.6834 | J16: =Historicals!F12 -> -7682
A17: Net sales | B17: =B15+B16 -> 8317 | C17: =C15+C16 -> 9481.9344 | D17: =IF(B17=0,0,C17/B17-1) -> 0.14006666 | E17: =E15+E16 -> 8536 | F17: =F15+F16 -> 9976.5181 | G17: =IF(E17=0,0,F17/E17-1) -> 0.16875798 | H17: =H15+H16 -> 17855 | I17: =I15+I16 -> 37313.453 | J17: =J15+J16 -> 33670 | K17: =IF(J17=0,0,I17/J17-1) -> 0.10821065
A19: Segment EBITDA
A20: Engine | B20: =Historicals!D18 -> 261 | C20: =C10*Inputs!$B$8 -> 410.68138 | D20: =IF(B20<=0,0,C20/B20-1) -> 0.57349186 | E20: =Historicals!E18 -> 263 | F20: =F10*Inputs!$C$8 -> 467.53434 | G20: =IF(E20<=0,0,F20/E20-1) -> 0.77769711 | H20: =Historicals!G18+Historicals!H18 -> 665 | I20: =H20+C20+F20 -> 1543.2157 | J20: =Historicals!F18 -> 1382 | K20: =IF(J20<=0,0,I20/J20-1) -> 0.11665392
A21: Components | B21: =Historicals!D19 -> 292 | C21: =C11*Inputs!$B$11 -> 384.9837 | D21: =IF(B21<=0,0,C21/B21-1) -> 0.31843733 | E21: =Historicals!E19 -> 327 | F21: =F11*Inputs!$C$11 -> 443.58412 | G21: =IF(E21<=0,0,F21/E21-1) -> 0.35652638 | H21: =Historicals!G19+Historicals!H19 -> 718 | I21: =H21+C21+F21 -> 1546.5678 | J21: =Historicals!F19 -> 1398 | K21: =IF(J21<=0,0,I21/J21-1) -> 0.10627169
A22: Distribution | B22: =Historicals!D20 -> 492 | C22: =C12*Inputs!$B$14 -> 489.40788 | D22: =IF(B22<=0,0,C22/B22-1) -> -0.0052685366 | E22: =Historicals!E20 -> 495 | F22: =F12*Inputs!$C$14 -> 525.10725 | G22: =IF(E22<=0,0,F22/E22-1) -> 0.060822727 | H22: =Historicals!G20+Historicals!H20 -> 895 | I22: =H22+C22+F22 -> 1909.5151 | J22: =Historicals!F20 -> 1808 | K22: =IF(J22<=0,0,I22/J22-1) -> 0.056147749
A23: Power Systems | B23: =Historicals!D21 -> 457 | C23: =C13*Inputs!$B$17 -> 565.2672 | D23: =IF(B23<=0,0,C23/B23-1) -> 0.23690853 | E23: =Historicals!E21 -> 418 | F23: =F13*Inputs!$C$17 -> 536.8407 | G23: =IF(E23<=0,0,F23/E23-1) -> 0.28430789 | H23: =Historicals!G21+Historicals!H21 -> 1129 | I23: =H23+C23+F23 -> 2231.1079 | J23: =Historicals!F21 -> 1694 | K23: =IF(J23<=0,0,I23/J23-1) -> 0.31706488
A24: Accelera | B24: =Historicals!D22 -> -336 | C24: =Inputs!$B$20 -> -65 | E24: =Historicals!E22 -> -374 | F24: =Inputs!$C$20 -> -65 | H24: =Historicals!G22+Historicals!H22 -> -346 | I24: =H24+C24+F24 -> -476 | J24: =Historicals!F22 -> -896
A25: Eliminations and corporate | B25: =Historicals!D23 -> 21 | C25: =Inputs!$B$22 -> -25 | E25: =Historicals!E23 -> 22 | F25: =Inputs!$C$22 -> -25 | H25: =Historicals!G23+Historicals!H23 -> -118 | I25: =H25+C25+F25 -> -168 | J25: =Historicals!F23 -> -1
A26: Total EBITDA (reported basis) | B26: =SUM(B20:B25) -> 1187 | C26: =SUM(C20:C25) -> 1760.3402 | D26: =IF(B26<=0,0,C26/B26-1) -> 0.48301614 | E26: =SUM(E20:E25) -> 1151 | F26: =SUM(F20:F25) -> 1883.0664 | G26: =IF(E26<=0,0,F26/E26-1) -> 0.63602642 | H26: =SUM(H20:H25) -> 2943 | I26: =SUM(I20:I25) -> 6586.4066 | J26: =SUM(J20:J25) -> 5385 | K26: =IF(J26<=0,0,I26/J26-1) -> 0.22310243
A27: EBITDA margin | B27: =IF(B17=0,0,B26/B17) -> 0.14271973 | C27: =IF(C17=0,0,C26/C17) -> 0.18565201 | E27: =IF(E17=0,0,E26/E17) -> 0.13484067 | F27: =IF(F17=0,0,F26/F17) -> 0.18874986 | H27: =IF(H17=0,0,H26/H17) -> 0.16482778 | I27: =IF(I17=0,0,I26/I17) -> 0.1765156 | J27: =IF(J17=0,0,J26/J17) -> 0.15993466
A28: Special items added back | B28: =Historicals!D28 -> 240 | C28: 0 | E28: =Historicals!E28 -> 218 | F28: 0 | H28: =Historicals!G28+Historicals!H28 -> 199 | I28: =H28+C28+F28 -> 199 | J28: =Historicals!F28 -> 458
A29: EBITDA excluding special items | B29: =B26+B28 -> 1427 | C29: =C26+C28 -> 1760.3402 | D29: =IF(B29<=0,0,C29/B29-1) -> 0.23359506 | E29: =E26+E28 -> 1369 | F29: =F26+F28 -> 1883.0664 | G29: =IF(E29<=0,0,F29/E29-1) -> 0.37550505 | H29: =H26+H28 -> 3142 | I29: =I26+I28 -> 6785.4066 | J29: =J26+J28 -> 5843 | K29: =IF(J29<=0,0,I29/J29-1) -> 0.16128813
A30: Adjusted EBITDA margin | B30: =IF(B17=0,0,B29/B17) -> 0.17157629 | C30: =IF(C17=0,0,C29/C17) -> 0.18565201 | E30: =IF(E17=0,0,E29/E17) -> 0.16037957 | F30: =IF(F17=0,0,F29/F17) -> 0.18874986 | H30: =IF(H17=0,0,H29/H17) -> 0.17597312 | I30: =IF(I17=0,0,I29/I17) -> 0.1818488 | J30: =IF(J17=0,0,J29/J17) -> 0.17353727
A32: FY2026 check against management guidance
A33: FY2026 revenue growth (budget) | B33: =K17 -> 0.10821065
A34: Guidance range | B34: =Inputs!$B$31 -> 0.1 | C34: =Inputs!$B$32 -> 0.13
A35: Revenue within guidance? | B35: =IF(AND(B33>=B34,B33<=C34),"Yes",IF(B33<B34,"Below","Above")) -> Yes
A36: FY2026 adjusted EBITDA margin (budget) | B36: =I30 -> 0.1818488
A37: Guidance range | B37: =Inputs!$B$33 -> 0.18 | C37: =Inputs!$B$34 -> 0.185
A38: EBITDA margin within guidance? | B38: =IF(AND(B36>=B37,B36<=C37),"Yes",IF(B36<B37,"Below","Above")) -> Yes
A39: H2 2026 implied net sales growth (YoY) | B39: =(C17+F17)/(B17+E17)-1 -> 0.15459874
A41: Adjusted EPS bridge (excludes special items)
B42: Q2 2026A tie-out | C42: Q3 2026B | F42: Q4 2026B
A43: Adjusted EBITDA | B43: =Historicals!H29 -> 1653 | C43: =C29 -> 1760.3402 | F43: =F29 -> 1883.0664
A44: Depreciation and amortization | B44: 280 | C44: =Inputs!$B$24 -> 285 | F44: =Inputs!$C$24 -> 290 | I44: Q2 2026 actuals from the Q2 2026 release: D&A $280M, interest $80M, tax $325M, NCI $36M, diluted EPS $6.73.
...

Sheet Variance
A1: Q3 2026 budget vs actual - variance bridge ($ millions) | I1: =HYPERLINK("#'Dashboard'!A1","← Back to Dashboard") -> ← Back to Dashboard
A2: Type Cummins' reported Q3 2026 figures into the yellow cells. Green = better than budget, red = worse. The bridge splits each gap into volume and margin.
A3: =IF(C11="","Waiting for Q3 2026 results (expected early November 2026). Type the actual figures into the yellow cells below.","Sales "&IF(D11>=0,"BEAT budget by ","MISSED budget by ")&TEXT(ABS(D11),"$#,##0")&"M"&IF(C20="","","; profit (EBITDA) "&IF(D20>=0,"BEAT budget by ","MISSED budget by ")&TEXT(ABS(D20),"$#,##0")&"M")) -> Waiting for Q3 2026 results (expected early November 2026). Type the actual figures into the yellow cells below.
A4: Sales | B4: Budget | C4: Actual | D4: Variance $ | E4: Variance %
A5: Engine | B5: =Forecast!C10 -> 3019.716 | D5: =IF(C5="","",C5-B5) | E5: =IF(OR(C5="",B5=0),"",C5/B5-1)
A6: Components | B6: =Forecast!C11 -> 2701.64 | D6: =IF(C6="","",C6-B6) | E6: =IF(OR(C6="",B6=0),"",C6/B6-1)
A7: Distribution | B7: =Forecast!C12 -> 3520.92 | D7: =IF(C7="","",C7-B7) | E7: =IF(OR(C7="",B7=0),"",C7/B7-1)
A8: Power Systems | B8: =Forecast!C13 -> 2355.28 | D8: =IF(C8="","",C8-B8) | E8: =IF(OR(C8="",B8=0),"",C8/B8-1)
A9: Accelera | B9: =Forecast!C14 -> 65.34 | D9: =IF(C9="","",C9-B9) | E9: =IF(OR(C9="",B9=0),"",C9/B9-1)
A10: Intersegment eliminations | B10: =Forecast!C16 -> -2180.9616 | D10: =IF(C10="","",C10-B10) | E10: =IF(OR(C10="",B10=0),"",C10/B10-1)
A11: Net sales | B11: =SUM(B5:B10) -> 9481.9344 | C11: =IF(COUNT(C5:C10)=0,"",SUM(C5:C10)) | D11: =IF(C11="","",C11-B11) | E11: =IF(OR(C11="",B11=0),"",C11/B11-1)
A13: EBITDA | B13: Budget | C13: Actual | D13: Variance $ | E13: Volume effect | F13: Margin effect | G13: Budget margin | H13: Actual margin | I13: How to read
A14: Engine | B14: =Forecast!C20 -> 410.68138 | D14: =IF(C14="","",C14-B14) | E14: =IF(OR(C14="",C5=""),"",(C5-B5)*G14) | F14: =IF(E14="","",D14-E14) | G14: =IF(B5=0,0,B14/B5) -> 0.136 | H14: =IF(OR(C14="",C5=""),"",C14/C5) | I14: Volume effect = sales variance x budget margin.
A15: Components | B15: =Forecast!C21 -> 384.9837 | D15: =IF(C15="","",C15-B15) | E15: =IF(OR(C15="",C6=""),"",(C6-B6)*G15) | F15: =IF(E15="","",D15-E15) | G15: =IF(B6=0,0,B15/B6) -> 0.1425 | H15: =IF(OR(C15="",C6=""),"",C15/C6) | I15: Margin effect = actual sales x (actual - budget margin).
A16: Distribution | B16: =Forecast!C22 -> 489.40788 | D16: =IF(C16="","",C16-B16) | E16: =IF(OR(C16="",C7=""),"",(C7-B7)*G16) | F16: =IF(E16="","",D16-E16) | G16: =IF(B7=0,0,B16/B7) -> 0.139 | H16: =IF(OR(C16="",C7=""),"",C16/C7) | I16: Volume + margin effects add up to the EBITDA variance.
A17: Power Systems | B17: =Forecast!C23 -> 565.2672 | D17: =IF(C17="","",C17-B17) | E17: =IF(OR(C17="",C8=""),"",(C8-B8)*G17) | F17: =IF(E17="","",D17-E17) | G17: =IF(B8=0,0,B17/B8) -> 0.24 | H17: =IF(OR(C17="",C8=""),"",C17/C8)
A18: Accelera | B18: =Forecast!C24 -> -65 | D18: =IF(C18="","",C18-B18) | F18: =D18 | I18: Accelera and corporate: whole variance shown as margin/cost.
A19: Eliminations and corporate | B19: =Forecast!C25 -> -25 | D19: =IF(C19="","",C19-B19) | F19: =D19
A20: Total EBITDA | B20: =SUM(B14:B19) -> 1760.3402 | C20: =IF(COUNT(C14:C19)=0,"",SUM(C14:C19)) | D20: =IF(C20="","",C20-B20) | E20: =IF(C20="","",SUM(E14:E19)) | F20: =IF(C20="","",SUM(F14:F19)) | G20: =IF(B11=0,0,B20/B11) -> 0.18565201 | H20: =IF(OR(C20="",C11=""),"",C20/C11)
A22: Engine price vs volume | B22: Budget | C22: Actual | D22: Variance
A23: Engine units | B23: =Forecast!C6 -> 151312 | D23: =IF(C23="","",C23-B23) | I23: Unit shipments: 'Engine Segment Sales by Market and Unit Shipments' table.
A24: Sales per unit ($000) | B24: =Forecast!C7 -> 19.956884 | C24: =IF(OR(C23="",C5=""),"",C5*1000/C23) | D24: =IF(C24="","",C24-B24)
A25: Sales variance from unit volume | D25: =IF(C23="","",D23*B24/1000)
A26: Sales variance from price/mix | D26: =IF(OR(D5="",D25=""),"",D5-D25)
A27: Engine sales variance (check) | D27: =IF(D25="","",D25+D26)
A30: Variance commentary (write after actuals are in)
A31: 1. Headline: net sales and EBITDA vs budget, in $ and %. Was the miss or beat driven by volume or margin?
A32: 2. Biggest segment variance: which segment, why (end markets, pricing, costs), and is it one-off or recurring?
A33: 3. Engine: how much of the sales variance was unit volume vs price/mix? What does that say about truck pre-buy timing?
A34: 4. Power Systems and Distribution: did data center demand track budget? Any capacity constraints?
A35: 5. Forecast implication: what would you change in Q4 2026 drivers, and does FY2026 still land inside guidance?

Sheet Backtest
A1: Backtest: how accurate is this forecasting method on quarters we already know?
A2: Method: take last year's same quarter and grow it at the latest quarter's year-over-year rate. Then compare with what Cummins actually reported.
A3: =HYPERLINK("#'Dashboard'!A1","← Back to Dashboard") -> ← Back to Dashboard
A4: Segment | B4: Same quarter last year | C4: Latest YoY trend | D4: Forecast | E4: Actual | F4: Error | G4: Size of miss
A5: Engine | B5: =Historicals!D45 -> 2913 | C5: =Historicals!C6/Historicals!C45-1 -> -0.079974611 | D5: =B5*(1+C5) -> 2680.034 | E5: =Historicals!D6 -> 2605 | F5: =D5/E5-1 -> 0.028803822 | G5: =ABS(F5) -> 0.028803822
A6: Components | B6: =Historicals!D46 -> 2724 | C6: =Historicals!C7/Historicals!C46-1 -> -0.092890677 | D6: =B6*(1+C6) -> 2470.9658 | E6: =Historicals!D7 -> 2329 | F6: =D6/E6-1 -> 0.060955687 | G6: =ABS(F6) -> 0.060955687
A7: Distribution | B7: =Historicals!D47 -> 2952 | C7: =Historicals!C8/Historicals!C47-1 -> 0.074938141 | D7: =B7*(1+C7) -> 3173.2174 | E7: =Historicals!D8 -> 3172 | F7: =D7/E7-1 -> 0.00038379297 | G7: =ABS(F7) -> 0.00038379297
A8: Power Systems | B8: =Historicals!D48 -> 1687 | C8: =Historicals!C9/Historicals!C48-1 -> 0.18879799 | D8: =B8*(1+C8) -> 2005.5022 | E8: =Historicals!D9 -> 1996 | F8: =D8/E8-1 -> 0.0047606226 | G8: =ABS(F8) -> 0.0047606226
A9: Four segments combined | D9: =SUM(D5:D8) -> 10329.719 | E9: =SUM(E5:E8) -> 10102 | F9: =D9/E9-1 -> 0.022542006 | G9: =ABS(F9) -> 0.022542006
A11: What the tests tell us
A12: These become the error bands on the Forecast tab (Check 4) and the size of the Bear/Bull scenarios on the Dashboard.
A13: Largest single-segment miss | G13: =MAX(G5:G8,G18:G21) -> 0.076468053
A14: Largest miss on the four-segment total | G14: =MAX(G9,G22) -> 0.022542006
A16: Test 2: forecast Q4 2025 as if it were November 2025
A17: Segment | B17: Same quarter last year | C17: Latest YoY trend | D17: Forecast | E17: Actual | F17: Error | G17: Size of miss
A18: Engine | B18: =Historicals!E45 -> 2720 | C18: =Historicals!D6/Historicals!D45-1 -> -0.10573292 | D18: =B18*(1+C18) -> 2432.4065 | E18: =Historicals!E6 -> 2600 | F18: =D18/E18-1 -> -0.064459056 | G18: =ABS(F18) -> 0.064459056
A19: Components | B19: =Historicals!E46 -> 2641 | C19: =Historicals!D7/Historicals!D46-1 -> -0.14500734 | D19: =B19*(1+C19) -> 2258.0356 | E19: =Historicals!E7 -> 2445 | F19: =D19/E19-1 -> -0.076468053 | G19: =ABS(F19) -> 0.076468053
A20: Distribution | B20: =Historicals!E47 -> 3068 | C20: =Historicals!D8/Historicals!D47-1 -> 0.074525745 | D20: =B20*(1+C20) -> 3296.645 | E20: =Historicals!E8 -> 3285 | F20: =D20/E20-1 -> 0.0035448969 | G20: =ABS(F20) -> 0.0035448969
A21: Power Systems | B21: =Historicals!E48 -> 1743 | C21: =Historicals!D9/Historicals!D48-1 -> 0.18316538 | D21: =B21*(1+C21) -> 2062.2573 | E21: =Historicals!E9 -> 1929 | F21: =D21/E21-1 -> 0.069081006 | G21: =ABS(F21) -> 0.069081006
A22: Four segments combined | D22: =SUM(D18:D21) -> 10049.344 | E22: =SUM(E18:E21) -> 10259 | F22: =D22/E22-1 -> -0.02043627 | G22: =ABS(F22) -> 0.02043627
A24: Lesson: simple trend-carrying overshoots when trucks turn down (Q3 2025) and undershoots when they recover (Q4 2025). That is why the v1.1 drivers are anchored to Cummins' own segment guidance instead of trend alone.

Sheet Change Log
A1: Change Log: v1.0 (Oct 7, 2026) to v1.1 (Oct 8, 2026), both locked before Q3 results
A2: v1.1 came from a structured review: five independent critiques, peer review, and backtests against public data. The Variance tab scores v1.1.
A3: =HYPERLINK("#'Dashboard'!A1","← Back to Dashboard") -> ← Back to Dashboard
A4: Driver | B4: v1.0 Q3 | C4: v1.0 Q4 | D4: v1.1 Q3 | E4: v1.1 Q4 | F4: Why it changed
A5: Engine unit growth (YoY) | B5: 0.13 | C5: 0.18 | D5: =Inputs!B6 -> 0.12 | E5: =Inputs!C6 -> 0.19 | F5: Re-sized so FY Engine sales sit inside Cummins' +9% to +14% guide; Q3 keeps a seasonal dip below Q2.
A6: Engine EBITDA margin | B6: 0.125 | C6: 0.135 | D6: =Inputs!B8 -> 0.136 | E6: =Inputs!C8 -> 0.146 | F6: v1.0 put FY Engine margin at 12.3%, below the 12.5%-13.25% guide.
A7: Components sales growth (YoY) | B7: 0.17 | C7: 0.2 | D7: =Inputs!B10 -> 0.16 | E7: =Inputs!C10 -> 0.23 | F7: Q3 lowered for seasonality, Q4 raised for the truck recovery; FY inside the +8% to +13% guide.
A8: Components EBITDA margin | B8: 0.135 | C8: 0.14 | D8: =Inputs!B11 -> 0.1425 | E8: =Inputs!C11 -> 0.1475 | F8: v1.0 sat at the bottom of the guide; now the guide midpoint.
A9: Distribution sales growth (YoY) | B9: 0.11 | C9: 0.11 | D9: =Inputs!B13 -> 0.11 | E9: =Inputs!C13 -> 0.15 | F9: H1 was +8.3%; Q4 raised so FY sits nearer the +9% to +14% guide midpoint.
A10: Distribution EBITDA margin | B10: 0.142 | C10: 0.142 | D10: =Inputs!B14 -> 0.139 | E10: =Inputs!C14 -> 0.139 | F10: v1.0 cited the old Q1 guide (13.7%-14.7%); the current guide is 13.5%-14.25%.
A11: Power Systems sales growth (YoY) | B11: 0.19 | C11: 0.19 | D11: =Inputs!B16 -> 0.18 | E11: =Inputs!C16 -> 0.15 | F11: Q4 2025 base is tougher; FY still near the top of the +14% to +19% guide.
A12: Power Systems EBITDA margin | B12: 0.255 | C12: 0.255 | D12: =Inputs!B17 -> 0.24 | E12: =Inputs!C17 -> 0.242 | F12: v1.0 put FY at 26.1%, above the 25.0%-25.75% guide.
A13: Accelera sales growth (YoY) | B13: 0.1 | C13: 0.1 | D13: =Inputs!B19 -> -0.46 | E13: =Inputs!C19 -> -0.5 | F13: v1.0 implied $523M vs the $350M-$400M guide (electrolyzer exit, fuel cell sale).
A14: Accelera EBITDA ($mm) | B14: -70 | C14: -65 | D14: =Inputs!B20 -> -65 | E14: =Inputs!C20 -> -65 | F14: Loss now inside the $260M-$290M guide.
A15: Eliminations (% of total segment sales) | B15: 0.19 | C15: 0.19 | D15: =Inputs!B21 -> 0.187 | E15: =Inputs!C21 -> 0.187 | F15: Now the four-quarter average instead of a rounded 19%.
A16: Eliminations and corporate EBITDA ($mm) | B16: -20 | C16: -20 | D16: =Inputs!B22 -> -25 | E16: =Inputs!C22 -> -25 | F16: Now sourced: Q2 -$48M plus about $25M per quarter lower incentive comp.
A18: Result | B18: v1.0 | D18: v1.1 | F18: Change
A19: Q3 2026 net sales ($mm) | B19: 9558.7 | D19: =Forecast!C17 -> 9481.9344 | F19: =D19-B19 -> -76.765552
A20: Q3 2026 adjusted EBITDA margin | B20: 0.1846 | D20: =Forecast!C30 -> 0.18565201 | F20: =D20-B20 -> 0.0010520065
A21: FY2026 net sales ($mm) | B21: 37291.9 | D21: =Forecast!I17 -> 37313.453 | F21: =D21-B21 -> 21.552568
A22: FY2026 adjusted EBITDA ($mm) | B22: 6763.9 | D22: =Forecast!I29 -> 6785.4066 | F22: =D22-B22 -> 21.506571
A23: FY2026 adjusted EBITDA margin | B23: 0.1814 | D23: =Forecast!I30 -> 0.1818488 | F23: =D23-B23 -> 0.00044879994
A24: Power Systems FY EBITDA margin | B24: 0.2612 | D24: =Forecast!F60 -> 0.25397859 | F24: =D24-B24 -> -0.0072214147
A25: Engine FY EBITDA margin | B25: 0.1231 | D25: =Forecast!F57 -> 0.12883745 | F25: =D25-B25 -> 0.0057374472
A27: Other fixes in v1.1
A28: - Added Check 1 (segment guidance), Check 2 (seasonality), Check 3 (Wall Street consensus) and Check 4 (accuracy band) to the Forecast tab.
A29: - Added an adjusted EPS bridge that ties to Q2 2026 reported EPS, so the budget can be compared with consensus EPS.
A30: - Added this Backtest tab and resized Bear/Bull scenarios to the method's real historical misses (symmetric, not hand-picked).
A31: - Rewrote every driver rationale to cite a dated source. Company totals are now outputs, not targets.

Sheet Historicals
A1: Historical segment results ($ millions)
A2: What Cummins actually reported, copied from its official SEC earnings releases. Check rows must show zero.
A3: =HYPERLINK("#'Dashboard'!A1","← Back to Dashboard") -> ← Back to Dashboard
B4: Q1 2025 | C4: Q2 2025 | D4: Q3 2025 | E4: Q4 2025 | F4: FY2025 | G4: Q1 2026 | H4: Q2 2026 | I4: Source / note
A5: Segment sales
A6: Engine | B6: 2771 | C6: 2899 | D6: 2605 | E6: 2600 | F6: =SUM(B6:E6) -> 10875 | G6: 2672 | H6: 3084 | I6: Q2'26 and 6M tables: Cummins Q2 2026 earnings release (8-K Ex.99, Aug 4 2026), segment tables: https://www.sec.gov/Archives/edgar/data/0000026172/000002617226000026/cmi2026q28-kex99.htm
A7: Components | B7: 2670 | C7: 2705 | D7: 2329 | E7: 2445 | F7: =SUM(B7:E7) -> 10149 | G7: 2530 | H7: 2891
A8: Distribution | B8: 2907 | C8: 3041 | D8: 3172 | E8: 3285 | F8: =SUM(B8:E8) -> 12405 | G8: 3116 | H8: 3326 | I8: Q3'25 table: Cummins Q3 2025 earnings release (8-K Ex.99, Nov 6 2025), segment table: https://www.sec.gov/Archives/edgar/data/26172/000002617225000036/cmi2025q38-kex99.htm
A9: Power Systems | B9: 1649 | C9: 1889 | D9: 1996 | E9: 1929 | F9: =SUM(B9:E9) -> 7463 | G9: 1956 | H9: 2255
A10: Accelera | B10: 103 | C10: 105 | D10: 121 | E10: 131 | F10: =SUM(B10:E10) -> 460 | G10: 101 | H10: 145 | I10: Q4'25 and FY25 tables: Cummins Q4/FY2025 earnings release (8-K Ex.99, Feb 5 2026), segment tables: https://www.sec.gov/Archives/edgar/data/26172/000002617226000004/cmi2025q48-kex99.htm
A11: Total segment sales | B11: =SUM(B6:B10) -> 10100 | C11: =SUM(C6:C10) -> 10639 | D11: =SUM(D6:D10) -> 10223 | E11: =SUM(E6:E10) -> 10390 | F11: =SUM(F6:F10) -> 41352 | G11: =SUM(G6:G10) -> 10375 | H11: =SUM(H6:H10) -> 11701
A12: Intersegment eliminations | B12: -1926 | C12: -1996 | D12: -1906 | E12: -1854 | F12: =SUM(B12:E12) -> -7682 | G12: -1977 | H12: -2244
A13: Net sales | B13: =B11+B12 -> 8174 | C13: =C11+C12 -> 8643 | D13: =D11+D12 -> 8317 | E13: =E11+E12 -> 8536 | F13: =F11+F12 -> 33670 | G13: =G11+G12 -> 8398 | H13: =H11+H12 -> 9457
A14: Reported net sales | B14: 8174 | C14: 8643 | D14: 8317 | E14: 8536 | F14: =SUM(B14:E14) -> 33670 | G14: 8398 | H14: 9457
A15: Check: model less reported (should be 0) | B15: =B13-B14 -> 0 | C15: =C13-C14 -> 0 | D15: =D13-D14 -> 0 | E15: =E13-E14 -> 0 | F15: =F13-F14 -> 0 | G15: =G13-G14 -> 0 | H15: =H13-H14 -> 0
A17: Segment EBITDA (reported, includes special items)
A18: Engine | B18: 458 | C18: 400 | D18: 261 | E18: 263 | F18: =SUM(B18:E18) -> 1382 | G18: 279 | H18: 386
A19: Components | B19: 382 | C19: 397 | D19: 292 | E19: 327 | F19: =SUM(B19:E19) -> 1398 | G19: 337 | H19: 381
A20: Distribution | B20: 376 | C20: 445 | D20: 492 | E20: 495 | F20: =SUM(B20:E20) -> 1808 | G20: 444 | H20: 451
A21: Power Systems | B21: 389 | C21: 430 | D21: 457 | E21: 418 | F21: =SUM(B21:E21) -> 1694 | G21: 577 | H21: 552
A22: Accelera | B22: -86 | C22: -100 | D22: -336 | E22: -374 | F22: =SUM(B22:E22) -> -896 | G22: -277 | H22: -69
A23: Eliminations and corporate | B23: -59 | C23: 15 | D23: 21 | E23: 22 | F23: =SUM(B23:E23) -> -1 | G23: -70 | H23: -48
A24: Total EBITDA | B24: =SUM(B18:B23) -> 1460 | C24: =SUM(C18:C23) -> 1587 | D24: =SUM(D18:D23) -> 1187 | E24: =SUM(E18:E23) -> 1151 | F24: =SUM(F18:F23) -> 5385 | G24: =SUM(G18:G23) -> 1290 | H24: =SUM(H18:H23) -> 1653
A25: EBITDA margin (% of net sales) | B25: =IF(B13=0,0,B24/B13) -> 0.17861512 | C25: =IF(C13=0,0,C24/C13) -> 0.1836168 | D25: =IF(D13=0,0,D24/D13) -> 0.14271973 | E25: =IF(E13=0,0,E24/E13) -> 0.13484067 | F25: =IF(F13=0,0,F24/F13) -> 0.15993466 | G25: =IF(G13=0,0,G24/G13) -> 0.153608 | H25: =IF(H13=0,0,H24/H13) -> 0.17479116
A26: Reported EBITDA | B26: 1460 | C26: 1587 | D26: 1187 | E26: 1151 | F26: =SUM(B26:E26) -> 5385 | G26: 1290 | H26: 1653
A27: Check: model less reported (should be 0) | B27: =B24-B26 -> 0 | C27: =C24-C26 -> 0 | D27: =D24-D26 -> 0 | E27: =E24-E26 -> 0 | F27: =F24-F26 -> 0 | G27: =G24-G26 -> 0 | H27: =H24-H26 -> 0
A28: Special items in Accelera (charges added back) | B28: 0 | C28: 0 | D28: 240 | E28: 218 | F28: =SUM(B28:E28) -> 458 | G28: 199 | H28: 0 | I28: Q3'25: $240 goodwill impairment + inventory write-down; Q4'25: $218 electrolyzer review; Q1'26: $199 fuel cell business sale.
A29: EBITDA excluding special items | B29: =B24+B28 -> 1460 | C29: =C24+C28 -> 1587 | D29: =D24+D28 -> 1427 | E29: =E24+E28 -> 1369 | F29: =F24+F28 -> 5843 | G29: =G24+G28 -> 1489 | H29: =H24+H28 -> 1653
A30: Adjusted EBITDA margin | B30: =IF(B13=0,0,B29/B13) -> 0.17861512 | C30: =IF(C13=0,0,C29/C13) -> 0.1836168 | D30: =IF(D13=0,0,D29/D13) -> 0.17157629 | E30: =IF(E13=0,0,E29/E13) -> 0.16037957 | F30: =IF(F13=0,0,F29/F13) -> 0.17353727 | G30: =IF(G13=0,0,G29/G13) -> 0.17730412 | H30: =IF(H13=0,0,H29/H13) -> 0.17479116
A32: Segment EBITDA margin (% of segment sales)
A33: Engine | B33: =IF(B6=0,0,B18/B6) -> 0.16528329 | C33: =IF(C6=0,0,C18/C6) -> 0.13797861 | D33: =IF(D6=0,0,D18/D6) -> 0.10019194 | E33: =IF(E6=0,0,E18/E6) -> 0.10115385 | F33: =IF(F6=0,0,F18/F6) -> 0.12708046 | G33: =IF(G6=0,0,G18/G6) -> 0.10441617 | H33: =IF(H6=0,0,H18/H6) -> 0.12516213
A34: Components | B34: =IF(B7=0,0,B19/B7) -> 0.14307116 | C34: =IF(C7=0,0,C19/C7) -> 0.14676525 | D34: =IF(D7=0,0,D19/D7) -> 0.1253757 | E34: =IF(E7=0,0,E19/E7) -> 0.13374233 | F34: =IF(F7=0,0,F19/F7) -> 0.13774756 | G34: =IF(G7=0,0,G19/G7) -> 0.13320158 | H34: =IF(H7=0,0,H19/H7) -> 0.13178831
A35: Distribution | B35: =IF(B8=0,0,B20/B8) -> 0.12934297 | C35: =IF(C8=0,0,C20/C8) -> 0.14633344 | D35: =IF(D8=0,0,D20/D8) -> 0.15510719 | E35: =IF(E8=0,0,E20/E8) -> 0.15068493 | F35: =IF(F8=0,0,F20/F8) -> 0.14574768 | G35: =IF(G8=0,0,G20/G8) -> 0.14249037 | H35: =IF(H8=0,0,H20/H8) -> 0.13559832
A36: Power Systems | B36: =IF(B9=0,0,B21/B9) -> 0.23590055 | C36: =IF(C9=0,0,C21/C9) -> 0.22763367 | D36: =IF(D9=0,0,D21/D9) -> 0.22895792 | E36: =IF(E9=0,0,E21/E9) -> 0.21669259 | F36: =IF(F9=0,0,F21/F9) -> 0.22698647 | G36: =IF(G9=0,0,G21/G9) -> 0.29498978 | H36: =IF(H9=0,0,H21/H9) -> 0.24478936
A37: Accelera: margin not meaningful (loss-making)
A39: Engine segment unit drivers
A40: Engine unit shipments (units) | B40: 141000 | C40: 147000 | D40: 135100 | E40: 131100 | F40: =SUM(B40:E40) -> 554200 | G40: 144300 | H40: 161200 | I40: Unit shipments exclude aftermarket parts; sales per unit therefore includes parts and price/mix.
A41: Engine sales per unit ($000) | B41: =IF(B40=0,0,B6*1000/B40) -> 19.652482 | C41: =IF(C40=0,0,C6*1000/C40) -> 19.721088 | D41: =IF(D40=0,0,D6*1000/D40) -> 19.282013 | E41: =IF(E40=0,0,E6*1000/E40) -> 19.832189 | F41: =IF(F40=0,0,F6*1000/F40) -> 19.62288 | G41: =IF(G40=0,0,G6*1000/G40) -> 18.516979 | H41: =IF(H40=0,0,H6*1000/H40) -> 19.131514
A43: 2024 segment sales (used for the seasonality check and the backtest)
B44: Q1 2024 | C44: Q2 2024 | D44: Q3 2024 | E44: Q4 2024
...

Sheet Scenario Calc
B1: Scenario Calc: the maths behind the scenario explorer ($ millions)
B2: Second-half 2026 sales = second-half 2025 sales x (1 + budget growth + scenario change). Profit = sales x (budget margin + change).
B3: =HYPERLINK("#'Dashboard'!A1","← Back to Dashboard") -> ← Back to Dashboard
B4: Business | C4: H2 2025 sales | D4: H2 2026 budget | E4: Budget growth | F4: Budget H2 EBITDA | G4: Budget margin | H4: Demand link
B5: Engine | C5: =Forecast!B10+Forecast!E10 -> 5205 | D5: =Forecast!C10+Forecast!F10 -> 6222.006 | E5: =D5/C5-1 -> 0.1953902 | F5: =Forecast!C20+Forecast!F20 -> 878.21572 | G5: =F5/D5 -> 0.14114672 | H5: Truck
B6: Components | C6: =Forecast!B11+Forecast!E11 -> 4774 | D6: =Forecast!C11+Forecast!F11 -> 5708.99 | E6: =D6/C6-1 -> 0.19585044 | F6: =Forecast!C21+Forecast!F21 -> 828.56782 | G6: =F6/D6 -> 0.14513387 | H6: Truck
B7: Distribution | C7: =Forecast!B12+Forecast!E12 -> 6457 | D7: =Forecast!C12+Forecast!F12 -> 7298.67 | E7: =D7/C7-1 -> 0.13035001 | F7: =Forecast!C22+Forecast!F22 -> 1014.5151 | G7: =F7/D7 -> 0.139 | H7: Data center
B8: Power Systems | C8: =Forecast!B13+Forecast!E13 -> 3925 | D8: =Forecast!C13+Forecast!F13 -> 4573.63 | E8: =D8/C8-1 -> 0.16525605 | F8: =Forecast!C23+Forecast!F23 -> 1102.1079 | G8: =F8/D8 -> 0.24097006 | H8: Data center
B9: Accelera H2 2026 budget (sales / EBITDA) | D9: =Forecast!C14+Forecast!F14 -> 130.84 | F9: =Forecast!C24+Forecast!F24 -> -130
B10: Eliminations and corporate H2 2026 EBITDA | F10: =Forecast!C25+Forecast!F25 -> -50
B11: Elimination ratio (% of total segment sales) | D11: =-(Forecast!C16+Forecast!F16)/(Forecast!C15+Forecast!F15) -> 0.187
B12: H1 2026 actual net sales | D12: =Forecast!H17 -> 17855
B13: H1 2026 actual adjusted EBITDA | D13: =Forecast!H29 -> 3142
B14: FY2025 net sales | D14: =Forecast!J17 -> 33670
B16: Scenario | C16: Bear | D16: Base | E16: Bull | F16: Custom | G16: Your pick
B17: Truck demand change | C17: =Dashboard!E18 -> -0.08 | D17: =Dashboard!F18 -> 0 | E17: =Dashboard!G18 -> 0.08 | F17: =Dashboard!H18 -> -0.05 | G17: =Dashboard!I18 -> 0
B18: Data center demand change | C18: =Dashboard!E19 -> -0.07 | D18: =Dashboard!F19 -> 0 | E18: =Dashboard!G19 -> 0.07 | F18: =Dashboard!H19 -> 0 | G18: =Dashboard!I19 -> 0
B19: Margin change | C19: =Dashboard!E20 -> -0.005 | D19: =Dashboard!F20 -> 0 | E19: =Dashboard!G20 -> 0.005 | F19: =Dashboard!H20 -> 0 | G19: =Dashboard!I20 -> 0
B20: H2 sales: Engine | C20: =$C5*(1+$E5+IF($H5="Truck",C$17,C$18)) -> 5805.606 | D20: =$C5*(1+$E5+IF($H5="Truck",D$17,D$18)) -> 6222.006 | E20: =$C5*(1+$E5+IF($H5="Truck",E$17,E$18)) -> 6638.406 | F20: =$C5*(1+$E5+IF($H5="Truck",F$17,F$18)) -> 5961.756 | G20: =$C5*(1+$E5+IF($H5="Truck",G$17,G$18)) -> 6222.006
B21: H2 sales: Components | C21: =$C6*(1+$E6+IF($H6="Truck",C$17,C$18)) -> 5327.07 | D21: =$C6*(1+$E6+IF($H6="Truck",D$17,D$18)) -> 5708.99 | E21: =$C6*(1+$E6+IF($H6="Truck",E$17,E$18)) -> 6090.91 | F21: =$C6*(1+$E6+IF($H6="Truck",F$17,F$18)) -> 5470.29 | G21: =$C6*(1+$E6+IF($H6="Truck",G$17,G$18)) -> 5708.99
B22: H2 sales: Distribution | C22: =$C7*(1+$E7+IF($H7="Truck",C$17,C$18)) -> 6846.68 | D22: =$C7*(1+$E7+IF($H7="Truck",D$17,D$18)) -> 7298.67 | E22: =$C7*(1+$E7+IF($H7="Truck",E$17,E$18)) -> 7750.66 | F22: =$C7*(1+$E7+IF($H7="Truck",F$17,F$18)) -> 7298.67 | G22: =$C7*(1+$E7+IF($H7="Truck",G$17,G$18)) -> 7298.67
B23: H2 sales: Power Systems | C23: =$C8*(1+$E8+IF($H8="Truck",C$17,C$18)) -> 4298.88 | D23: =$C8*(1+$E8+IF($H8="Truck",D$17,D$18)) -> 4573.63 | E23: =$C8*(1+$E8+IF($H8="Truck",E$17,E$18)) -> 4848.38 | F23: =$C8*(1+$E8+IF($H8="Truck",F$17,F$18)) -> 4573.63 | G23: =$C8*(1+$E8+IF($H8="Truck",G$17,G$18)) -> 4573.63
B24: H2 sales: Accelera | C24: =$D$9 -> 130.84 | D24: =$D$9 -> 130.84 | E24: =$D$9 -> 130.84 | F24: =$D$9 -> 130.84 | G24: =$D$9 -> 130.84
B25: H2 total segment sales | C25: =SUM(C20:C24) -> 22409.076 | D25: =SUM(D20:D24) -> 23934.136 | E25: =SUM(E20:E24) -> 25459.196 | F25: =SUM(F20:F24) -> 23435.186 | G25: =SUM(G20:G24) -> 23934.136
B26: H2 eliminations | C26: =-C25*$D$11 -> -4190.4972 | D26: =-D25*$D$11 -> -4475.6834 | E26: =-E25*$D$11 -> -4760.8697 | F26: =-F25*$D$11 -> -4382.3798 | G26: =-G25*$D$11 -> -4475.6834
B27: H2 net sales | C27: =C25+C26 -> 18218.579 | D27: =D25+D26 -> 19458.453 | E27: =E25+E26 -> 20698.326 | F27: =F25+F26 -> 19052.806 | G27: =G25+G26 -> 19458.453
B29: FY2026 net sales | C29: =$D$12+C27 -> 36073.579 | D29: =$D$12+D27 -> 37313.453 | E29: =$D$12+E27 -> 38553.326 | F29: =$D$12+F27 -> 36907.806 | G29: =$D$12+G27 -> 37313.453
B30: FY2026 sales growth | C30: =C29/$D$14-1 -> 0.071386361 | D30: =D29/$D$14-1 -> 0.10821065 | E30: =E29/$D$14-1 -> 0.14503494 | F30: =F29/$D$14-1 -> 0.096162941 | G30: =G29/$D$14-1 -> 0.10821065
B31: H2 EBITDA: Engine | C31: =C20*($G5+C$19) -> 790.41419 | D31: =D20*($G5+D$19) -> 878.21572 | E31: =E20*($G5+E$19) -> 970.18124 | F31: =F20*($G5+F$19) -> 841.48228 | G31: =G20*($G5+G$19) -> 878.21572
B32: H2 EBITDA: Components | C32: =C21*($G6+C$19) -> 746.50295 | D32: =D21*($G6+D$19) -> 828.56782 | E32: =E21*($G6+E$19) -> 914.4519 | F32: =F21*($G6+F$19) -> 793.92437 | G32: =G21*($G6+G$19) -> 828.56782
B33: H2 EBITDA: Distribution | C33: =C22*($G7+C$19) -> 917.45512 | D33: =D22*($G7+D$19) -> 1014.5151 | E33: =E22*($G7+E$19) -> 1116.095 | F33: =F22*($G7+F$19) -> 1014.5151 | G33: =G22*($G7+G$19) -> 1014.5151
B34: H2 EBITDA: Power Systems | C34: =C23*($G8+C$19) -> 1014.407 | D34: =D23*($G8+D$19) -> 1102.1079 | E34: =E23*($G8+E$19) -> 1192.5563 | F34: =F23*($G8+F$19) -> 1102.1079 | G34: =G23*($G8+G$19) -> 1102.1079
B35: H2 EBITDA: Accelera, eliminations and corporate | C35: =$F$9+$F$10 -> -180 | D35: =$F$9+$F$10 -> -180 | E35: =$F$9+$F$10 -> -180 | F35: =$F$9+$F$10 -> -180 | G35: =$F$9+$F$10 -> -180
B36: H2 adjusted EBITDA | C36: =SUM(C31:C35) -> 3288.7792 | D36: =SUM(D31:D35) -> 3643.4066 | E36: =SUM(E31:E35) -> 4013.2845 | F36: =SUM(F31:F35) -> 3572.0297 | G36: =SUM(G31:G35) -> 3643.4066
B37: FY2026 adjusted EBITDA | C37: =$D$13+C36 -> 6430.7792 | D37: =$D$13+D36 -> 6785.4066 | E37: =$D$13+E36 -> 7155.2845 | F37: =$D$13+F36 -> 6714.0297 | G37: =$D$13+G36 -> 6785.4066
B38: FY2026 adjusted EBITDA margin | C38: =C37/C29 -> 0.1782684 | D38: =D37/D29 -> 0.1818488 | E38: =E37/E29 -> 0.18559448 | F38: =F37/F29 -> 0.18191354 | G38: =G37/G29 -> 0.1818488
B40: Check: Base sales less Forecast (should be 0) | D40: =D29-Forecast!I17 -> 0
B41: Check: Base EBITDA less Forecast (should be 0) | D41: =D37-Forecast!I29 -> 0

Sheet Chart Data
A1: Quarter | B1: Actual sales ($B) | C1: Forecast sales ($B) | D1: Actual margin | E1: Forecast margin
A2: Q1 '25 | B2: =Historicals!B13/1000 -> 8.174 | D2: =Historicals!B30 -> 0.17861512
A3: Q2 '25 | B3: =Historicals!C13/1000 -> 8.643 | D3: =Historicals!C30 -> 0.1836168
A4: Q3 '25 | B4: =Historicals!D13/1000 -> 8.317 | D4: =Historicals!D30 -> 0.17157629
A5: Q4 '25 | B5: =Historicals!E13/1000 -> 8.536 | D5: =Historicals!E30 -> 0.16037957
A6: Q1 '26 | B6: =Historicals!G13/1000 -> 8.398 | D6: =Historicals!G30 -> 0.17730412
A7: Q2 '26 | B7: =Historicals!H13/1000 -> 9.457 | D7: =Historicals!H30 -> 0.17479116 | E7: =Historicals!H30 -> 0.17479116
A8: Q3 '26 | C8: =Forecast!C17/1000 -> 9.4819344 | E8: =Forecast!C30 -> 0.18565201
A9: Q4 '26 | C9: =Forecast!F17/1000 -> 9.9765181 | E9: =Forecast!F30 -> 0.18874986
A11: Business | B11: 2026 sales growth | D11: =HYPERLINK("#'Dashboard'!A1","← Back to Dashboard") -> ← Back to Dashboard
A12: Engine | B12: =Forecast!K10 -> 0.10142584
A13: Components | B13: =Forecast!K11 -> 0.096658784
A14: Distribution | B14: =Forecast!K12 -> 0.10767191
A15: Power Systems | B15: =Forecast!K13 -> 0.17709098
A16: Accelera | B16: =Forecast!K14 -> -0.18078261
A18: Scenario | B18: FY2026 adjusted EBITDA ($B)
A19: Bear | B19: ='Scenario Calc'!C37/1000 -> 6.4307792
A20: Base | B20: ='Scenario Calc'!D37/1000 -> 6.7854066
A21: Bull | B21: ='Scenario Calc'!E37/1000 -> 7.1552845
A22: Custom | B22: ='Scenario Calc'!F37/1000 -> 6.7140297
